Workbook

Sheet Cover
B2: GE VERNOVA INC. (NYSE: GEV)
B3: Discounted Cash Flow Valuation Model
B5: Analyst: | C5: Jonathan
B6: Date: | C6: April 14, 2026
B7: Model version: | C7: v1.0 skeleton
B9: MODEL STRUCTURE
B11: Tab | C11: Description
B12: Cover | C12: This sheet — summary, sources, color conventions
B13: Assumptions | C13: All forecast assumptions (revenue growth, margins, WACC). BLUE cells are inputs.
B14: Revenue | C14: Segment & sub-segment revenue build
B15: P&L | C15: Income statement forecast, bridges to Adj EBITDA
B16: FCF | C16: Free cash flow build (EBITDA → unlevered FCF)
B17: DCF | C17: Discounting, terminal value, equity bridge, per-share valuation
B18: Sensitivity | C18: WACC vs terminal growth; WACC vs exit multiple
B19: Historicals | C19: Clean historical pull from 10-K (source of truth for baseline)
B22: COLOR CONVENTIONS
B24: Blue | C24: Hardcoded inputs / assumptions you can change
B25: Black | C25: Formulas and calculations
B26: Green | C26: Links from other sheets
B27: Yellow fill | C27: Key assumptions requiring attention
B30: KEY SOURCES
B32: GEV 2025 10-K | C32: https://www.sec.gov/Archives/edgar/data/0001996810/000199681026000015/gev-20251231.htm
B33: GEV Q4 2025 Press Release (8-K) | C33: https://www.sec.gov/Archives/edgar/data/0001996810/000199681026000012/gevpressrelease4q25.htm
B34: GEV Investor Relations | C34: https://www.gevernova.com/investors
B37: HEALTH WARNINGS
B39: 1. 2025 reported net income ($4,879M) includes a $2.9B one-time tax valuation allowance release. Use normalized ~25-28% tax rate for forecasting.
B40: 2. GEV has near-zero debt. WACC ≈ Ke. Post-Prolec (~$2.65B debt), D/(D+E) still < 2%.
B41: 3. Pension non-operating income of ~$459M/year flows below operating line but is real. Do not exclude from net income.
B42: 4. Wind segment has $3.3B goodwill with only 27% cushion. Offshore wind pause (Dec 22, 2025) is a real impairment risk.
B43: 5. Prolec acquisition closes Feb 2026 for $5.3B. Model should reflect full-year 2026 contribution.

Sheet Assumptions
B2: KEY ASSUMPTIONS
B4: All inputs in BLUE. Edit these cells to change the model.
B6: Year | C6: 2023A | D6: 2024A | E6: 2025A | F6: 2026E | G6: 2027E | H6: 2028E | I6: 2029E | J6: 2030E
B8: REVENUE GROWTH ASSUMPTIONS (YoY)
B10: Gas Power | F10: =Scenarios!F20 -> 0.15 | G10: =Scenarios!F21 -> 0.13 | H10: =Scenarios!F22 -> 0.11 | I10: =Scenarios!F23 -> 0.09 | J10: =Scenarios!F24 -> 0.07
B11: Nuclear Power | F11: =Scenarios!F25 -> 0.15 | G11: =Scenarios!F26 -> 0.15 | H11: =Scenarios!F27 -> 0.14 | I11: =Scenarios!F28 -> 0.12 | J11: =Scenarios!F29 -> 0.1
B12: Hydro Power | F12: =Scenarios!F30 -> 0.03 | G12: =Scenarios!F31 -> 0.03 | H12: =Scenarios!F32 -> 0.03 | I12: =Scenarios!F33 -> 0.03 | J12: =Scenarios!F34 -> 0.03
B13: Steam Power | F13: =Scenarios!F35 -> -0.04 | G13: =Scenarios!F36 -> -0.04 | H13: =Scenarios!F37 -> -0.04 | I13: =Scenarios!F38 -> -0.03 | J13: =Scenarios!F39 -> -0.03
B14: Onshore Wind | F14: =Scenarios!F40 -> 0.02 | G14: =Scenarios!F41 -> 0.03 | H14: =Scenarios!F42 -> 0.04 | I14: =Scenarios!F43 -> 0.04 | J14: =Scenarios!F44 -> 0.04
B15: Offshore Wind | F15: =Scenarios!F45 -> -0.3 | G15: =Scenarios!F46 -> -0.15 | H15: =Scenarios!F47 -> 0 | I15: =Scenarios!F48 -> 0.05 | J15: =Scenarios!F49 -> 0.05
B16: LM Wind Power | F16: =Scenarios!F50 -> -0.15 | G16: =Scenarios!F51 -> -0.05 | H16: =Scenarios!F52 -> 0.02 | I16: =Scenarios!F53 -> 0.03 | J16: =Scenarios!F54 -> 0.03
B17: Grid Solutions | F17: =Scenarios!F55 -> 0.61 | G17: =Scenarios!F56 -> 0.15 | H17: =Scenarios!F57 -> 0.12 | I17: =Scenarios!F58 -> 0.1 | J17: =Scenarios!F59 -> 0.08
B18: Power Conversion & Storage | F18: =Scenarios!F60 -> 0.18 | G18: =Scenarios!F61 -> 0.15 | H18: =Scenarios!F62 -> 0.13 | I18: =Scenarios!F63 -> 0.11 | J18: =Scenarios!F64 -> 0.09
B19: Electrification Software | F19: =Scenarios!F65 -> 0.08 | G19: =Scenarios!F66 -> 0.08 | H19: =Scenarios!F67 -> 0.07 | I19: =Scenarios!F68 -> 0.06 | J19: =Scenarios!F69 -> 0.06
B22: SEGMENT EBITDA MARGIN ASSUMPTIONS
B24: Power EBITDA margin | C24: 0.099 | D24: 0.125 | E24: 0.147 | F24: =Scenarios!F72 -> 0.16 | G24: =Scenarios!F73 -> 0.17 | H24: =Scenarios!F74 -> 0.175 | I24: =Scenarios!F75 -> 0.18 | J24: =Scenarios!F76 -> 0.18
B25: Wind EBITDA margin | C25: -0.105 | D25: -0.061 | E25: -0.066 | F25: =Scenarios!F77 -> -0.045 | G25: =Scenarios!F78 -> -0.025 | H25: =Scenarios!F79 -> -0.01 | I25: =Scenarios!F80 -> 0.005 | J25: =Scenarios!F81 -> 0.015
B26: Electrification EBITDA margin | C26: 0.037 | D26: 0.09 | E26: 0.149 | F26: =Scenarios!F82 -> 0.17 | G26: =Scenarios!F83 -> 0.18 | H26: =Scenarios!F84 -> 0.185 | I26: =Scenarios!F85 -> 0.19 | J26: =Scenarios!F86 -> 0.19
B27: Corporate & other ($M, negative) | C27: -116 | D27: -323 | E27: -541 | F27: -560 | G27: -580 | H27: -600 | I27: -620 | J27: -640
B30: OTHER P&L ASSUMPTIONS
B32: D&A as % of revenue | C32: 0.029 | D32: 0.034 | E32: 0.022 | F32: 0.028 | G32: 0.027 | H32: 0.026 | I32: 0.025 | J32: 0.025
B33: Stock-based comp ($M) | C33: 0 | D33: 155 | E33: 257 | F33: 290 | G33: 310 | H33: 330 | I33: 350 | J33: 370
B34: Pension / postretirement income ($M) | C34: 567 | D34: 536 | E34: 459 | F34: 500 | G34: 510 | H34: 520 | I34: 530 | J34: 540
B35: Effective tax rate (normalized) | C35: 0.264 | D35: 0.376 | E35: 0.27 | F35: 0.25 | G35: 0.25 | H35: 0.25 | I35: 0.25 | J35: 0.25
B36: Restructuring & other ($M) | C36: 433 | D36: 421 | E36: 285 | F36: 150 | G36: 100 | H36: 75 | I36: 50 | J36: 50
B39: CAPEX & WORKING CAPITAL ASSUMPTIONS
B41: CapEx as % of revenue | C41: 0.022 | D41: 0.025 | E41: 0.033 | F41: 0.0375 | G41: 0.034 | H41: 0.031 | I41: 0.029 | J41: 0.0275
B42: Change in NWC as % of revenue change | F42: -0.3 | G42: -0.15 | H42: -0.05 | I42: 0 | J42: 0.05
B45: WACC & VALUATION ASSUMPTIONS
B47: Risk-free rate (10Y UST) | C47: 0.043 | D47: Source: FRED DGS10, avg last 30 days
B48: Equity risk premium | C48: 0.055 | D48: Source: Damodaran implied ERP, trailing avg
B49: Beta (2Y weekly vs S&P 500) | C49: =Scenarios!F89 -> 1.3 | D49: Source: Bloomberg BETA function
B50: Cost of equity (CAPM) | C50: =C47 + C49 * C48 -> 0.1145 | D50: Formula: Rf + Beta × ERP
B51: Pre-tax cost of debt | C51: 0.055 | D51: Post-Prolec; BBB/BBB+ rated
B52: Tax rate (for after-tax Kd) | C52: 0.25
B53: After-tax cost of debt | C53: =C51 * (1 - C52) -> 0.04125 | D53: Formula: Kd × (1 - t)
B54: Target debt weight | C54: 0.02 | D54: Post-Prolec; near-zero debt structure
B55: Target equity weight | C55: =1 - C54 -> 0.98 | D55: Formula: 1 - debt weight
B56: WACC | C56: =C50*C55 + C53*C54 -> 0.113035 | D56: Formula: Ke × We + Kd × (1-t) × Wd
B58: Terminal growth rate (g) | C58: =Scenarios!F90 -> 0.025 | D58: Long-run nominal GDP proxy
...

Sheet Revenue
B2: REVENUE BUILD — SEGMENT & SUB-SEGMENT
B3: Historicals pulled from Historicals tab. Forecasts driven by growth rates on Assumptions tab.
B5: Year | C5: 2023A | D5: 2024A | E5: 2025A | F5: 2026E | G5: 2027E | H5: 2028E | I5: 2029E | J5: 2030E
B7: SUB-SEGMENT REVENUE ($M)
B9: Gas Power | C9: =Historicals!C9 -> 13220 | D9: =Historicals!D9 -> 14465 | E9: =Historicals!E9 -> 16006 | F9: =E9*(1+Assumptions!F10) -> 18406.9 | G9: =F9*(1+Assumptions!G10) -> 20799.797 | H9: =G9*(1+Assumptions!H10) -> 23087.775 | I9: =H9*(1+Assumptions!I10) -> 25165.674 | J9: =I9*(1+Assumptions!J10) -> 26927.272
B10: Nuclear Power | C10: =Historicals!C10 -> 827 | D10: =Historicals!D10 -> 819 | E10: =Historicals!E10 -> 1018 | F10: =E10*(1+Assumptions!F11) -> 1170.7 | G10: =F10*(1+Assumptions!G11) -> 1346.305 | H10: =G10*(1+Assumptions!H11) -> 1534.7877 | I10: =H10*(1+Assumptions!I11) -> 1718.9622 | J10: =I10*(1+Assumptions!J11) -> 1890.8584
B11: Hydro Power | C11: =Historicals!C11 -> 887 | D11: =Historicals!D11 -> 781 | E11: =Historicals!E11 -> 806 | F11: =E11*(1+Assumptions!F12) -> 830.18 | G11: =F11*(1+Assumptions!G12) -> 855.0854 | H11: =G11*(1+Assumptions!H12) -> 880.73796 | I11: =H11*(1+Assumptions!I12) -> 907.1601 | J11: =I11*(1+Assumptions!J12) -> 934.3749
B12: Steam Power | C12: =Historicals!C12 -> 2502 | D12: =Historicals!D12 -> 2063 | E12: =Historicals!E12 -> 1937 | F12: =E12*(1+Assumptions!F13) -> 1859.52 | G12: =F12*(1+Assumptions!G13) -> 1785.1392 | H12: =G12*(1+Assumptions!H13) -> 1713.7336 | I12: =H12*(1+Assumptions!I13) -> 1662.3216 | J12: =I12*(1+Assumptions!J13) -> 1612.452
B13: Onshore Wind | C13: =Historicals!C14 -> 7761 | D13: =Historicals!D14 -> 7781 | E13: =Historicals!E14 -> 8241 | F13: =E13*(1+Assumptions!F14) -> 8405.82 | G13: =F13*(1+Assumptions!G14) -> 8657.9946 | H13: =G13*(1+Assumptions!H14) -> 9004.3144 | I13: =H13*(1+Assumptions!I14) -> 9364.487 | J13: =I13*(1+Assumptions!J14) -> 9739.0664
B14: Offshore Wind | C14: =Historicals!C15 -> 1455 | D14: =Historicals!D15 -> 1377 | E14: =Historicals!E15 -> 652 | F14: =E14*(1+Assumptions!F15) -> 456.4 | G14: =F14*(1+Assumptions!G15) -> 387.94 | H14: =G14*(1+Assumptions!H15) -> 387.94 | I14: =H14*(1+Assumptions!I15) -> 407.337 | J14: =I14*(1+Assumptions!J15) -> 427.70385
B15: LM Wind Power | C15: =Historicals!C16 -> 610 | D15: =Historicals!D16 -> 542 | E15: =Historicals!E16 -> 217 | F15: =E15*(1+Assumptions!F16) -> 184.45 | G15: =F15*(1+Assumptions!G16) -> 175.2275 | H15: =G15*(1+Assumptions!H16) -> 178.73205 | I15: =H15*(1+Assumptions!I16) -> 184.09401 | J15: =I15*(1+Assumptions!J16) -> 189.61683
B16: Grid Solutions | C16: =Historicals!C18 -> 3955 | D16: =Historicals!D18 -> 4957 | E16: =Historicals!E18 -> 6620 | F16: =E16*(1+Assumptions!F17) -> 10658.2 | G16: =F16*(1+Assumptions!G17) -> 12256.93 | H16: =G16*(1+Assumptions!H17) -> 13727.762 | I16: =H16*(1+Assumptions!I17) -> 15100.538 | J16: =I16*(1+Assumptions!J17) -> 16308.581
B17: Power Conversion & Storage | C17: =Historicals!C19 -> 1548 | D17: =Historicals!D19 -> 1676 | E17: =Historicals!E19 -> 2049 | F17: =E17*(1+Assumptions!F18) -> 2417.82 | G17: =F17*(1+Assumptions!G18) -> 2780.493 | H17: =G17*(1+Assumptions!H18) -> 3141.9571 | I17: =H17*(1+Assumptions!I18) -> 3487.5724 | J17: =I17*(1+Assumptions!J18) -> 3801.4539
B18: Electrification Software | C18: =Historicals!C20 -> 874 | D18: =Historicals!D20 -> 917 | E18: =Historicals!E20 -> 973 | F18: =E18*(1+Assumptions!F19) -> 1050.84 | G18: =F18*(1+Assumptions!G19) -> 1134.9072 | H18: =G18*(1+Assumptions!H19) -> 1214.3507 | I18: =H18*(1+Assumptions!I19) -> 1287.2117 | J18: =I18*(1+Assumptions!J19) -> 1364.4445
B20: Power segment total | C20: =C9+C10+C11+C12 -> 17436 | D20: =D9+D10+D11+D12 -> 18128 | E20: =E9+E10+E11+E12 -> 19767 | F20: =F9+F10+F11+F12 -> 22267.3 | G20: =G9+G10+G11+G12 -> 24786.327 | H20: =H9+H10+H11+H12 -> 27217.034 | I20: =I9+I10+I11+I12 -> 29454.118 | J20: =J9+J10+J11+J12 -> 31364.957
B22: Wind segment total | C22: =C13+C14+C15 -> 9826 | D22: =D13+D14+D15 -> 9700 | E22: =E13+E14+E15 -> 9110 | F22: =F13+F14+F15 -> 9046.67 | G22: =G13+G14+G15 -> 9221.1621 | H22: =H13+H14+H15 -> 9570.9864 | I22: =I13+I14+I15 -> 9955.918 | J22: =J13+J14+J15 -> 10356.387
B24: Electrification segment total | C24: =C16+C17+C18 -> 6377 | D24: =D16+D17+D18 -> 7550 | E24: =E16+E17+E18 -> 9642 | F24: =F16+F17+F18 -> 14126.86 | G24: =G16+G17+G18 -> 16172.33 | H24: =H16+H17+H18 -> 18084.069 | I24: =I16+I17+I18 -> 19875.322 | J24: =J16+J17+J18 -> 21474.479
B26: Eliminations & other | C26: =Historicals!C22 -> -401 | D26: =Historicals!D22 -> -442 | E26: =Historicals!E22 -> -451 | F26: =E26 -> -451 | G26: =F26 -> -451 | H26: =G26 -> -451 | I26: =H26 -> -451 | J26: =I26 -> -451
B28: TOTAL REVENUE | C28: =C20+C22+C24+C26 -> 33238 | D28: =D20+D22+D24+D26 -> 34936 | E28: =E20+E22+E24+E26 -> 38068 | F28: =F20+F22+F24+F26 -> 44989.83 | G28: =G20+G22+G24+G26 -> 49728.819 | H28: =H20+H22+H24+H26 -> 54421.09 | I28: =I20+I22+I24+I26 -> 58834.358 | J28: =J20+J22+J24+J26 -> 62744.823
B30: YoY growth % | D30: =D28/C28-1 -> 0.051086106 | E30: =E28/D28-1 -> 0.089649645 | F30: =F28/E28-1 -> 0.18182804 | G30: =G28/F28-1 -> 0.10533467 | H30: =H28/G28-1 -> 0.094357175 | I30: =I28/H28-1 -> 0.081094818 | J30: =J28/I28-1 -> 0.066465669

Sheet P&L
B2: P&L / EBITDA BUILD
B3: Segment EBITDA margins from Assumptions. Bridges to Adj EBITDA and to Net Income.
B5: Year | C5: 2023A | D5: 2024A | E5: 2025A | F5: 2026E | G5: 2027E | H5: 2028E | I5: 2029E | J5: 2030E
B7: REVENUE (from Revenue tab)
B9: Power revenue | C9: =Revenue!C20 -> 17436 | D9: =Revenue!D20 -> 18128 | E9: =Revenue!E20 -> 19767 | F9: =Revenue!F20 -> 22267.3 | G9: =Revenue!G20 -> 24786.327 | H9: =Revenue!H20 -> 27217.034 | I9: =Revenue!I20 -> 29454.118 | J9: =Revenue!J20 -> 31364.957
B10: Wind revenue | C10: =Revenue!C22 -> 9826 | D10: =Revenue!D22 -> 9700 | E10: =Revenue!E22 -> 9110 | F10: =Revenue!F22 -> 9046.67 | G10: =Revenue!G22 -> 9221.1621 | H10: =Revenue!H22 -> 9570.9864 | I10: =Revenue!I22 -> 9955.918 | J10: =Revenue!J22 -> 10356.387
B11: Electrification revenue | C11: =Revenue!C24 -> 6377 | D11: =Revenue!D24 -> 7550 | E11: =Revenue!E24 -> 9642 | F11: =Revenue!F24 -> 14126.86 | G11: =Revenue!G24 -> 16172.33 | H11: =Revenue!H24 -> 18084.069 | I11: =Revenue!I24 -> 19875.322 | J11: =Revenue!J24 -> 21474.479
B12: Total revenue | C12: =Revenue!C28 -> 33238 | D12: =Revenue!D28 -> 34936 | E12: =Revenue!E28 -> 38068 | F12: =Revenue!F28 -> 44989.83 | G12: =Revenue!G28 -> 49728.819 | H12: =Revenue!H28 -> 54421.09 | I12: =Revenue!I28 -> 58834.358 | J12: =Revenue!J28 -> 62744.823
B14: SEGMENT EBITDA
B16: Power EBITDA | C16: =C9*Assumptions!C24 -> 1726.164 | D16: =D9*Assumptions!D24 -> 2266 | E16: =E9*Assumptions!E24 -> 2905.749 | F16: =F9*Assumptions!F24 -> 3562.768 | G16: =G9*Assumptions!G24 -> 4213.6755 | H16: =H9*Assumptions!H24 -> 4762.9809 | I16: =I9*Assumptions!I24 -> 5301.7413 | J16: =J9*Assumptions!J24 -> 5645.6922
B17: Wind EBITDA | C17: =C10*Assumptions!C25 -> -1031.73 | D17: =D10*Assumptions!D25 -> -591.7 | E17: =E10*Assumptions!E25 -> -601.26 | F17: =F10*Assumptions!F25 -> -407.10015 | G17: =G10*Assumptions!G25 -> -230.52905 | H17: =H10*Assumptions!H25 -> -95.709864 | I17: =I10*Assumptions!I25 -> 49.77959 | J17: =J10*Assumptions!J25 -> 155.34581
B18: Electrification EBITDA | C18: =C11*Assumptions!C26 -> 235.949 | D18: =D11*Assumptions!D26 -> 679.5 | E18: =E11*Assumptions!E26 -> 1436.658 | F18: =F11*Assumptions!F26 -> 2401.5662 | G18: =G11*Assumptions!G26 -> 2911.0194 | H18: =H11*Assumptions!H26 -> 3345.5528 | I18: =I11*Assumptions!I26 -> 3776.3112 | J18: =J11*Assumptions!J26 -> 4080.151
B19: Corporate & other | C19: =Assumptions!C27 -> -116 | D19: =Assumptions!D27 -> -323 | E19: =Assumptions!E27 -> -541 | F19: =Assumptions!F27 -> -560 | G19: =Assumptions!G27 -> -580 | H19: =Assumptions!H27 -> -600 | I19: =Assumptions!I27 -> -620 | J19: =Assumptions!J27 -> -640
B21: Adjusted EBITDA | C21: =C16+C17+C18+C19 -> 814.383 | D21: =D16+D17+D18+D19 -> 2030.8 | E21: =E16+E17+E18+E19 -> 3200.147 | F21: =F16+F17+F18+F19 -> 4997.2341 | G21: =G16+G17+G18+G19 -> 6314.1659 | H21: =H16+H17+H18+H19 -> 7412.8239 | I21: =I16+I17+I18+I19 -> 8507.832 | J21: =J16+J17+J18+J19 -> 9241.1891
B23: Adj EBITDA margin | C23: =C21/C12 -> 0.024501564 | D23: =D21/D12 -> 0.05812915 | E23: =E21/E12 -> 0.084063964 | F23: =F21/F12 -> 0.11107475 | G23: =G21/G12 -> 0.12697197 | H23: =H21/H12 -> 0.13621234 | I23: =I21/I12 -> 0.14460652 | J23: =J21/J12 -> 0.1472821
B26: BRIDGE FROM ADJ EBITDA TO NET INCOME
B28: Less: D&A (% of revenue) | C28: =-C12*Assumptions!C32 -> -963.902 | D28: =-D12*Assumptions!D32 -> -1187.824 | E28: =-E12*Assumptions!E32 -> -837.496 | F28: =-F12*Assumptions!F32 -> -1259.7152 | G28: =-G12*Assumptions!G32 -> -1342.6781 | H28: =-H12*Assumptions!H32 -> -1414.9483 | I28: =-I12*Assumptions!I32 -> -1470.859 | J28: =-J12*Assumptions!J32 -> -1568.6206
B29: Less: Stock-based compensation | C29: =-Assumptions!C33 -> 0 | D29: =-Assumptions!D33 -> -155 | E29: =-Assumptions!E33 -> -257 | F29: =-Assumptions!F33 -> -290 | G29: =-Assumptions!G33 -> -310 | H29: =-Assumptions!H33 -> -330 | I29: =-Assumptions!I33 -> -350 | J29: =-Assumptions!J33 -> -370
B30: Less: Restructuring & other | C30: =-Assumptions!C36 -> -433 | D30: =-Assumptions!D36 -> -421 | E30: =-Assumptions!E36 -> -285 | F30: =-Assumptions!F36 -> -150 | G30: =-Assumptions!G36 -> -100 | H30: =-Assumptions!H36 -> -75 | I30: =-Assumptions!I36 -> -50 | J30: =-Assumptions!J36 -> -50
B32: Operating Income (approx) | C32: =C21+C28+C29+C30 -> -582.519 | D32: =D21+D28+D29+D30 -> 266.976 | E32: =E21+E28+E29+E30 -> 1820.651 | F32: =F21+F28+F29+F30 -> 3297.5188 | G32: =G21+G28+G29+G30 -> 4561.4878 | H32: =H21+H28+H29+H30 -> 5592.8756 | I32: =I21+I28+I29+I30 -> 6636.9731 | J32: =J21+J28+J29+J30 -> 7252.5685
B34: Add: Non-operating benefit income (pension) | C34: =Assumptions!C34 -> 567 | D34: =Assumptions!D34 -> 536 | E34: =Assumptions!E34 -> 459 | F34: =Assumptions!F34 -> 500 | G34: =Assumptions!G34 -> 510 | H34: =Assumptions!H34 -> 520 | I34: =Assumptions!I34 -> 530 | J34: =Assumptions!J34 -> 540
B36: Pre-tax income | C36: =C32+C34 -> -15.519 | D36: =D32+D34 -> 802.976 | E36: =E32+E34 -> 2279.651 | F36: =F32+F34 -> 3797.5188 | G36: =G32+G34 -> 5071.4878 | H36: =H32+H34 -> 6112.8756 | I36: =I32+I34 -> 7166.9731 | J36: =J32+J34 -> 7792.5685
B38: Less: Tax provision (normalized) | C38: =-C36*Assumptions!C35 -> 4.097016 | D38: =-D36*Assumptions!D35 -> -301.91898 | E38: =-E36*Assumptions!E35 -> -615.50577 | F38: =-F36*Assumptions!F35 -> -949.3797 | G38: =-G36*Assumptions!G35 -> -1267.8719 | H38: =-H36*Assumptions!H35 -> -1528.2189 | I38: =-I36*Assumptions!I35 -> -1791.7433 | J38: =-J36*Assumptions!J35 -> -1948.1421
B40: Net Income (normalized) | C40: =C36+C38 -> -11.421984 | D40: =D36+D38 -> 501.05702 | E40: =E36+E38 -> 1664.1452 | F40: =F36+F38 -> 2848.1391 | G40: =G36+G38 -> 3803.6158 | H40: =H36+H38 -> 4584.6567 | I40: =I36+I38 -> 5375.2298 | J40: =J36+J38 -> 5844.4264
B42: Diluted WASO (M) | C42: =Historicals!C63 -> 274 | D42: =Historicals!D63 -> 278 | E42: =Historicals!E63 -> 276 | F42: 272 | G42: 268 | H42: 264 | I42: 261 | J42: 258
B43: Normalized EPS ($/share) | C43: =C40/C42 -> -0.041686073 | D43: =D40/D42 -> 1.8023634 | E43: =E40/E42 -> 6.0295117 | F43: =F40/F42 -> 10.4711 | G43: =G40/G42 -> 14.192596 | H43: =H40/H42 -> 17.366124 | I43: =I40/I42 -> 20.59475 | J43: =J40/J42 -> 22.652815

Sheet FCF
B2: UNLEVERED FREE CASH FLOW BUILD
B3: EBITDA - tax on EBIT - CapEx - ΔNWC = Unlevered FCF
B5: Year | C5: 2023A | D5: 2024A | E5: 2025A | F5: 2026E | G5: 2027E | H5: 2028E | I5: 2029E | J5: 2030E
B7: Total Revenue | C7: =Revenue!C28 -> 33238 | D7: =Revenue!D28 -> 34936 | E7: =Revenue!E28 -> 38068 | F7: =Revenue!F28 -> 44989.83 | G7: =Revenue!G28 -> 49728.819 | H7: =Revenue!H28 -> 54421.09 | I7: =Revenue!I28 -> 58834.358 | J7: =Revenue!J28 -> 62744.823
B9: Adjusted EBITDA | C9: ='P&L'!C21 -> 814.383 | D9: ='P&L'!D21 -> 2030.8 | E9: ='P&L'!E21 -> 3200.147 | F9: ='P&L'!F21 -> 4997.2341 | G9: ='P&L'!G21 -> 6314.1659 | H9: ='P&L'!H21 -> 7412.8239 | I9: ='P&L'!I21 -> 8507.832 | J9: ='P&L'!J21 -> 9241.1891
B10: Less: D&A | C10: ='P&L'!C28 -> -963.902 | D10: ='P&L'!D28 -> -1187.824 | E10: ='P&L'!E28 -> -837.496 | F10: ='P&L'!F28 -> -1259.7152 | G10: ='P&L'!G28 -> -1342.6781 | H10: ='P&L'!H28 -> -1414.9483 | I10: ='P&L'!I28 -> -1470.859 | J10: ='P&L'!J28 -> -1568.6206
B11: EBIT | C11: =C9+C10 -> -149.519 | D11: =D9+D10 -> 842.976 | E11: =E9+E10 -> 2362.651 | F11: =F9+F10 -> 3737.5188 | G11: =G9+G10 -> 4971.4878 | H11: =H9+H10 -> 5997.8756 | I11: =I9+I10 -> 7036.9731 | J11: =J9+J10 -> 7672.5685
B13: Less: Tax on EBIT (NOPAT approach) | C13: =-C11*Assumptions!C35 -> 39.473016 | D13: =-D11*Assumptions!D35 -> -316.95898 | E13: =-E11*Assumptions!E35 -> -637.91577 | F13: =-F11*Assumptions!F35 -> -934.3797 | G13: =-G11*Assumptions!G35 -> -1242.8719 | H13: =-H11*Assumptions!H35 -> -1499.4689 | I13: =-I11*Assumptions!I35 -> -1759.2433 | J13: =-J11*Assumptions!J35 -> -1918.1421
B14: NOPAT | C14: =C11+C13 -> -110.04598 | D14: =D11+D13 -> 526.01702 | E14: =E11+E13 -> 1724.7352 | F14: =F11+F13 -> 2803.1391 | G14: =G11+G13 -> 3728.6158 | H14: =H11+H13 -> 4498.4067 | I14: =I11+I13 -> 5277.7298 | J14: =J11+J13 -> 5754.4264
B16: Add: D&A (non-cash) | C16: =-'P&L'!C28 -> 963.902 | D16: =-'P&L'!D28 -> 1187.824 | E16: =-'P&L'!E28 -> 837.496 | F16: =-'P&L'!F28 -> 1259.7152 | G16: =-'P&L'!G28 -> 1342.6781 | H16: =-'P&L'!H28 -> 1414.9483 | I16: =-'P&L'!I28 -> 1470.859 | J16: =-'P&L'!J28 -> 1568.6206
B17: Less: CapEx | C17: =-C7*Assumptions!C41 -> -731.236 | D17: =-D7*Assumptions!D41 -> -873.4 | E17: =-E7*Assumptions!E41 -> -1256.244 | F17: =-F7*Assumptions!F41 -> -1687.1186 | G17: =-G7*Assumptions!G41 -> -1690.7798 | H17: =-H7*Assumptions!H41 -> -1687.0538 | I17: =-I7*Assumptions!I41 -> -1706.1964 | J17: =-J7*Assumptions!J41 -> -1725.4826
B18: Less: Δ Net Working Capital | C18: 0 | D18: 0 | E18: 0 | F18: =(F7-E7)*Assumptions!F42 -> -2076.549 | G18: =(G7-F7)*Assumptions!G42 -> -710.84834 | H18: =(H7-G7)*Assumptions!H42 -> -234.61354 | I18: =(I7-H7)*Assumptions!I42 -> 0 | J18: =(J7-I7)*Assumptions!J42 -> 195.52325
B20: Unlevered Free Cash Flow | C20: =C14+C16+C17+C18 -> 122.62002 | D20: =D14+D16+D17+D18 -> 840.44102 | E20: =E14+E16+E17+E18 -> 1305.9872 | F20: =F14+F16+F17+F18 -> 299.18672 | G20: =G14+G16+G17+G18 -> 2669.6658 | H20: =H14+H16+H17+H18 -> 3991.6877 | I20: =I14+I16+I17+I18 -> 5042.3924 | J20: =J14+J16+J17+J18 -> 5793.0876
B22: Unlevered FCF margin | C22: =C20/C7 -> 0.0036891515 | D22: =D20/D7 -> 0.02405659 | E22: =E20/E7 -> 0.034306694 | F22: =F20/F7 -> 0.0066500968 | G22: =G20/G7 -> 0.05368448 | H22: =H20/H7 -> 0.073348176 | I22: =I20/I7 -> 0.085704893 | J22: =J20/J7 -> 0.092327738
B23: Unlevered FCF YoY growth | D23: =IFERROR(D20/C20-1,"-") -> 5.854028 | E23: =IFERROR(E20/D20-1,"-") -> 0.55393084 | F23: =IFERROR(F20/E20-1,"-") -> -0.77091145 | G23: =IFERROR(G20/F20-1,"-") -> 7.9230757 | H23: =IFERROR(H20/G20-1,"-") -> 0.49520128 | I23: =IFERROR(I20/H20-1,"-") -> 0.26322317 | J23: =IFERROR(J20/I20-1,"-") -> 0.14887679

Sheet DCF
B2: DCF VALUATION
B3: Discounting forecast UFCF at WACC; Gordon growth terminal value + exit multiple sanity check.
B5: Valuation date | C5: April 14, 2026
B7: WACC (linked from Assumptions) | C7: =Assumptions!C56 -> 0.113035
B8: Terminal growth rate (g) | C8: =Assumptions!C58 -> 0.025
B9: Exit EV/EBITDA multiple | C9: =Assumptions!C59 -> 18
B12: Year | C12: 2026E | D12: 2027E | E12: 2028E | F12: 2029E | G12: 2030E
B13: Period | C13: 1 | D13: 2 | E13: 3 | F13: 4 | G13: 5
B14: Unlevered FCF ($M) | C14: =FCF!F20 -> 299.18672 | D14: =FCF!G20 -> 2669.6658 | E14: =FCF!H20 -> 3991.6877 | F14: =FCF!I20 -> 5042.3924 | G14: =FCF!J20 -> 5793.0876
B15: Discount factor | C15: =1/(1+$C$7)^C13 -> 0.89844434 | D15: =1/(1+$C$7)^D13 -> 0.80720224 | E15: =1/(1+$C$7)^E13 -> 0.72522629 | F15: =1/(1+$C$7)^F13 -> 0.65157545 | G15: =1/(1+$C$7)^G13 -> 0.58540428
B16: PV of Unlevered FCF | C16: =C14*C15 -> 268.80262 | D16: =D14*D15 -> 2154.9602 | E16: =E14*E15 -> 2894.8768 | F16: =F14*F15 -> 3285.4991 | G16: =G14*G15 -> 3391.2983
B18: Sum of PV(FCF) — explicit period | C18: =SUM(C16:G16) -> 11995.437
B20: TERMINAL VALUE
B22: Method 1: Gordon Growth
B23: Terminal FCF (Yr 5 × (1+g)) | C23: =G14*(1+C8) -> 5937.9148
B24: Terminal Value (undiscounted) | C24: =C23/(C7-C8) -> 67449.478
B25: PV of Terminal Value | C25: =C24*G15 -> 39485.213
B27: Method 2: Exit Multiple (EV/EBITDA)
B28: Year 5 EBITDA | C28: ='P&L'!J21 -> 9241.1891
B29: Terminal EV (EBITDA × multiple) | C29: =C28*C9 -> 166341.4
B30: PV of Terminal Value (Exit Mult) | C30: =C29*G15 -> 97376.97
B32: ENTERPRISE VALUE
B34: EV (Gordon Growth method) | C34: =C18+C25 -> 51480.65
B35: EV (Exit Multiple method) — sanity check | C35: =C18+C30 -> 109372.41
B37: EQUITY BRIDGE (using Gordon Growth EV)
B39: Enterprise Value | C39: =C34 -> 51480.65
B40: Less: Total debt | C40: -2750
B41: Less: Pension underfunding | C41: -1500
B42: Less: Non-controlling interests | C42: -1118
B43: Add: Cash & equivalents | C43: 8848
B44: Add: Equity method investments | C44: 1834
B45: EQUITY VALUE | C45: =SUM(C39:C44) -> 56794.65
B47: Diluted shares outstanding (M) | C47: 260
B48: IMPLIED PRICE PER SHARE | C48: =C45/C47 -> 218.44096
B50: Current market price (as of 4/14/26) | C50: 995
B51: Implied upside/(downside) | C51: =C48/C50-1 -> -0.78046135

Sheet Historicals
B2: HISTORICAL FINANCIALS (from 2025 10-K)
B3: All figures $M unless noted. Source: GE Vernova 2025 Form 10-K filed January 29, 2026.
B5: Year | C5: 2023A | D5: 2024A | E5: 2025A | F5: 2026E | G5: 2027E | H5: 2028E | I5: 2029E | J5: 2030E
B7: REVENUE BY SUB-SEGMENT
B9: Gas Power | C9: 13220 | D9: 14465 | E9: 16006
B10: Nuclear Power | C10: 827 | D10: 819 | E10: 1018
B11: Hydro Power | C11: 887 | D11: 781 | E11: 806
B12: Steam Power | C12: 2502 | D12: 2063 | E12: 1937
B13: Power segment total | C13: 17436 | D13: 18127 | E13: 19767
B14: Onshore Wind | C14: 7761 | D14: 7781 | E14: 8241
B15: Offshore Wind | C15: 1455 | D15: 1377 | E15: 652
B16: LM Wind Power | C16: 610 | D16: 542 | E16: 217
B17: Wind segment total | C17: 9826 | D17: 9701 | E17: 9110
B18: Grid Solutions | C18: 3955 | D18: 4957 | E18: 6620
B19: Power Conversion & Storage | C19: 1548 | D19: 1676 | E19: 2049
B20: Electrification Software | C20: 874 | D20: 917 | E20: 973
... B23: Total Revenue | C23: 33239 | D23: 34935 | E23: 38068
B25: SEGMENT EBITDA
B27: Power | C27: 1722 | D27: 2268 | E27: 2902
B28: Wind | C28: -1033 | D28: -588 | E28: -598
B29: Electrification | C29: 234 | D29: 679 | E29: 1433
B30: Corporate & other | C30: -116 | D30: -323 | E30: -541
B31: Adjusted EBITDA | C31: 807 | D31: 2035 | E31: 3196
B34: INCOME STATEMENT KEY LINES
B36: Equipment revenue | C36: 18258 | D36: 18952 | E36: 20934
B37: Services revenue | C37: 14981 | D37: 15983 | E37: 17134
B38: Cost of equipment | C38: 18705 | D38: 17989 | E38: 18759
B39: Cost of services | C39: 9716 | D39: 10861 | E39: 11774
B40: Gross profit | C40: 4818 | D40: 6085 | E40: 7535
B41: SG&A | C41: 4845 | D41: 4632 | E41: 4949
B42: R&D | C42: 896 | D42: 982 | E42: 1197
B43: Operating income | C43: -923 | D43: 471 | E43: 1388
B44: Non-operating benefit income | C44: 567 | D44: 536 | E44: 459
B45: Interest & other financial inc (chg) | C45: -98 | D45: 120 | E45: 186
B46: Other income (expense) – net | C46: 324 | D46: 1372 | E46: 795
B47: Pre-tax income | C47: -130 | D47: 2498 | E47: 2828
... B50: D&A (PP&E + intangibles) | C50: 964 | D50: 1172 | E50: 853
B52: CASH FLOW
B54: Cash from operations | C54: 1186 | D54: 2583 | E54: 4987
B55: CapEx (PP&E + software) | C55: -744 | D55: -883 | E55: -1277
...

Sheet Sensitivity
B2: SENSITIVITY ANALYSIS
B3: Live formulas. Grid shows implied price/share across WACC and terminal assumptions.
B5: Forecast UFCF (from FCF tab — do not edit)
C6: 2026E | D6: 2027E | E6: 2028E | F6: 2029E | G6: 2030E
B7: Unlevered FCF | C7: =FCF!F20 -> 299.18672 | D7: =FCF!G20 -> 2669.6658 | E7: =FCF!H20 -> 3991.6877 | F7: =FCF!I20 -> 5042.3924 | G7: =FCF!J20 -> 5793.0876
B8: 2030E EBITDA | C8: ='P&L'!J21 -> 9241.1891
B10: Equity Bridge Adjustments ($M, from DCF tab)
B11: Less: Total debt (post-Prolec) | C11: -2750
B12: Less: Pension underfunding | C12: -1500
B13: Less: Non-controlling interests | C13: -1118
B14: Add: Cash | C14: 8848
B15: Add: Equity investments | C15: 1834
B16: Net bridge adjustment | C16: =SUM(C11:C15) -> 5314
B17: Diluted shares (M) | C17: 260
B20: TABLE 1: Implied Price/Share — Gordon Growth Method
B21: Rows = terminal growth (g). Columns = WACC.
B23: g \ WACC | C23: 0.095 | D23: 0.105 | E23: 0.113 | F23: 0.12 | G23: 0.13
B24: 0.015 | C24: =IF(C23<=B24,"-",((C7/(1+C23)^1 + D7/(1+C23)^2 + E7/(1+C23)^3 + F7/(1+C23)^4 + G7/(1+C23)^5)+G7*(1+B24)/(C23-B24)/(1+C23)^5+$C$16)/$C$17) -> 248.96322 | D24: =IF(D23<=B24,"-",((C7/(1+D23)^1 + D7/(1+D23)^2 + E7/(1+D23)^3 + F7/(1+D23)^4 + G7/(1+D23)^5)+G7*(1+B24)/(D23-B24)/(1+D23)^5+$C$16)/$C$17) -> 220.32841 | E24: =IF(E23<=B24,"-",((C7/(1+E23)^1 + D7/(1+E23)^2 + E7/(1+E23)^3 + F7/(1+E23)^4 + G7/(1+E23)^5)+G7*(1+B24)/(E23-B24)/(1+E23)^5+$C$16)/$C$17) -> 201.69417 | F24: =IF(F23<=B24,"-",((C7/(1+F23)^1 + D7/(1+F23)^2 + E7/(1+F23)^3 + F7/(1+F23)^4 + G7/(1+F23)^5)+G7*(1+B24)/(F23-B24)/(1+F23)^5+$C$16)/$C$17) -> 187.76184 | G24: =IF(G23<=B24,"-",((C7/(1+G23)^1 + D7/(1+G23)^2 + E7/(1+G23)^3 + F7/(1+G23)^4 + G7/(1+G23)^5)+G7*(1+B24)/(G23-B24)/(1+G23)^5+$C$16)/$C$17) -> 170.86258
B25: 0.02 | C25: =IF(C23<=B25,"-",((C7/(1+C23)^1 + D7/(1+C23)^2 + E7/(1+C23)^3 + F7/(1+C23)^4 + G7/(1+C23)^5)+G7*(1+B25)/(C23-B25)/(1+C23)^5+$C$16)/$C$17) -> 261.87836 | D25: =IF(D23<=B25,"-",((C7/(1+D23)^1 + D7/(1+D23)^2 + E7/(1+D23)^3 + F7/(1+D23)^4 + G7/(1+D23)^5)+G7*(1+B25)/(D23-B25)/(1+D23)^5+$C$16)/$C$17) -> 230.0962 | E25: =IF(E23<=B25,"-",((C7/(1+E23)^1 + D7/(1+E23)^2 + E7/(1+E23)^3 + F7/(1+E23)^4 + G7/(1+E23)^5)+G7*(1+B25)/(E23-B25)/(1+E23)^5+$C$16)/$C$17) -> 209.65974 | F25: =IF(F23<=B25,"-",((C7/(1+F23)^1 + D7/(1+F23)^2 + E7/(1+F23)^3 + F7/(1+F23)^4 + G7/(1+F23)^5)+G7*(1+B25)/(F23-B25)/(1+F23)^5+$C$16)/$C$17) -> 194.50472 | G25: =IF(G23<=B25,"-",((C7/(1+G23)^1 + D7/(1+G23)^2 + E7/(1+G23)^3 + F7/(1+G23)^4 + G7/(1+G23)^5)+G7*(1+B25)/(G23-B25)/(1+G23)^5+$C$16)/$C$17) -> 176.26394
B26: 0.025 | C26: =IF(C23<=B26,"-",((C7/(1+C23)^1 + D7/(1+C23)^2 + E7/(1+C23)^3 + F7/(1+C23)^4 + G7/(1+C23)^5)+G7*(1+B26)/(C23-B26)/(1+C23)^5+$C$16)/$C$17) -> 276.63852 | D26: =IF(D23<=B26,"-",((C7/(1+D23)^1 + D7/(1+D23)^2 + E7/(1+D23)^3 + F7/(1+D23)^4 + G7/(1+D23)^5)+G7*(1+B26)/(D23-B26)/(1+D23)^5+$C$16)/$C$17) -> 241.08496 | E26: =IF(E23<=B26,"-",((C7/(1+E23)^1 + D7/(1+E23)^2 + E7/(1+E23)^3 + F7/(1+E23)^4 + G7/(1+E23)^5)+G7*(1+B26)/(E23-B26)/(1+E23)^5+$C$16)/$C$17) -> 218.5305 | F26: =IF(F23<=B26,"-",((C7/(1+F23)^1 + D7/(1+F23)^2 + E7/(1+F23)^3 + F7/(1+F23)^4 + G7/(1+F23)^5)+G7*(1+B26)/(F23-B26)/(1+F23)^5+$C$16)/$C$17) -> 201.95737 | G26: =IF(G23<=B26,"-",((C7/(1+G23)^1 + D7/(1+G23)^2 + E7/(1+G23)^3 + F7/(1+G23)^4 + G7/(1+G23)^5)+G7*(1+B26)/(G23-B26)/(1+G23)^5+$C$16)/$C$17) -> 182.1797
B27: 0.03 | C27: =IF(C23<=B27,"-",((C7/(1+C23)^1 + D7/(1+C23)^2 + E7/(1+C23)^3 + F7/(1+C23)^4 + G7/(1+C23)^5)+G7*(1+B27)/(C23-B27)/(1+C23)^5+$C$16)/$C$17) -> 293.66947 | D27: =IF(D23<=B27,"-",((C7/(1+D23)^1 + D7/(1+D23)^2 + E7/(1+D23)^3 + F7/(1+D23)^4 + G7/(1+D23)^5)+G7*(1+B27)/(D23-B27)/(1+D23)^5+$C$16)/$C$17) -> 253.53889 | E27: =IF(E23<=B27,"-",((C7/(1+E23)^1 + D7/(1+E23)^2 + E7/(1+E23)^3 + F7/(1+E23)^4 + G7/(1+E23)^5)+G7*(1+B27)/(E23-B27)/(1+E23)^5+$C$16)/$C$17) -> 228.47001 | F27: =IF(F23<=B27,"-",((C7/(1+F23)^1 + D7/(1+F23)^2 + E7/(1+F23)^3 + F7/(1+F23)^4 + G7/(1+F23)^5)+G7*(1+B27)/(F23-B27)/(1+F23)^5+$C$16)/$C$17) -> 210.2381 | G27: =IF(G23<=B27,"-",((C7/(1+G23)^1 + D7/(1+G23)^2 + E7/(1+G23)^3 + F7/(1+G23)^4 + G7/(1+G23)^5)+G7*(1+B27)/(G23-B27)/(1+G23)^5+$C$16)/$C$17) -> 188.68704
B28: 0.035 | C28: =IF(C23<=B28,"-",((C7/(1+C23)^1 + D7/(1+C23)^2 + E7/(1+C23)^3 + F7/(1+C23)^4 + G7/(1+C23)^5)+G7*(1+B28)/(C23-B28)/(1+C23)^5+$C$16)/$C$17) -> 313.53891 | D28: =IF(D23<=B28,"-",((C7/(1+D23)^1 + D7/(1+D23)^2 + E7/(1+D23)^3 + F7/(1+D23)^4 + G7/(1+D23)^5)+G7*(1+B28)/(D23-B28)/(1+D23)^5+$C$16)/$C$17) -> 267.77195 | E28: =IF(E23<=B28,"-",((C7/(1+E23)^1 + D7/(1+E23)^2 + E7/(1+E23)^3 + F7/(1+E23)^4 + G7/(1+E23)^5)+G7*(1+B28)/(E23-B28)/(1+E23)^5+$C$16)/$C$17) -> 239.68383 | F28: =IF(F23<=B28,"-",((C7/(1+F23)^1 + D7/(1+F23)^2 + E7/(1+F23)^3 + F7/(1+F23)^4 + G7/(1+F23)^5)+G7*(1+B28)/(F23-B28)/(1+F23)^5+$C$16)/$C$17) -> 219.49304 | G28: =IF(G23<=B28,"-",((C7/(1+G23)^1 + D7/(1+G23)^2 + E7/(1+G23)^3 + F7/(1+G23)^4 + G7/(1+G23)^5)+G7*(1+B28)/(G23-B28)/(1+G23)^5+$C$16)/$C$17) -> 195.87937
B30: Base case (WACC 11.3%, g 2.5%) highlighted in green
B31: Current market price: $995
B34: TABLE 2: Implied Price/Share — Exit EV/EBITDA Multiple Method
B35: Rows = exit multiple. Columns = WACC.
B37: Mult \ WACC | C37: 0.095 | D37: 0.105 | E37: 0.113 | F37: 0.12 | G37: 0.13
B38: 12 | C38: =((C7/(1+C37)^1 + D7/(1+C37)^2 + E7/(1+C37)^3 + F7/(1+C37)^4 + G7/(1+C37)^5)+$C$8*B38/(1+C37)^5+$C$16)/$C$17 -> 340.32477 | D38: =((C7/(1+D37)^1 + D7/(1+D37)^2 + E7/(1+D37)^3 + F7/(1+D37)^4 + G7/(1+D37)^5)+$C$8*B38/(1+D37)^5+$C$16)/$C$17 -> 326.69607 | E38: =((C7/(1+E37)^1 + D7/(1+E37)^2 + E7/(1+E37)^3 + F7/(1+E37)^4 + G7/(1+E37)^5)+$C$8*B38/(1+E37)^5+$C$16)/$C$17 -> 316.3038 | F38: =((C7/(1+F37)^1 + D7/(1+F37)^2 + E7/(1+F37)^3 + F7/(1+F37)^4 + G7/(1+F37)^5)+$C$8*B38/(1+F37)^5+$C$16)/$C$17 -> 307.56403 | G38: =((C7/(1+G37)^1 + D7/(1+G37)^2 + E7/(1+G37)^3 + F7/(1+G37)^4 + G7/(1+G37)^5)+$C$8*B38/(1+G37)^5+$C$16)/$C$17 -> 295.62216
B39: 15 | C39: =((C7/(1+C37)^1 + D7/(1+C37)^2 + E7/(1+C37)^3 + F7/(1+C37)^4 + G7/(1+C37)^5)+$C$8*B39/(1+C37)^5+$C$16)/$C$17 -> 408.05853 | D39: =((C7/(1+D37)^1 + D7/(1+D37)^2 + E7/(1+D37)^3 + F7/(1+D37)^4 + G7/(1+D37)^5)+$C$8*B39/(1+D37)^5+$C$16)/$C$17 -> 391.41993 | E39: =((C7/(1+E37)^1 + D7/(1+E37)^2 + E7/(1+E37)^3 + F7/(1+E37)^4 + G7/(1+E37)^5)+$C$8*B39/(1+E37)^5+$C$16)/$C$17 -> 378.73475 | F39: =((C7/(1+F37)^1 + D7/(1+F37)^2 + E7/(1+F37)^3 + F7/(1+F37)^4 + G7/(1+F37)^5)+$C$8*B39/(1+F37)^5+$C$16)/$C$17 -> 368.06825 | G39: =((C7/(1+G37)^1 + D7/(1+G37)^2 + E7/(1+G37)^3 + F7/(1+G37)^4 + G7/(1+G37)^5)+$C$8*B39/(1+G37)^5+$C$16)/$C$17 -> 353.49617
B40: 18 | C40: =((C7/(1+C37)^1 + D7/(1+C37)^2 + E7/(1+C37)^3 + F7/(1+C37)^4 + G7/(1+C37)^5)+$C$8*B40/(1+C37)^5+$C$16)/$C$17 -> 475.79229 | D40: =((C7/(1+D37)^1 + D7/(1+D37)^2 + E7/(1+D37)^3 + F7/(1+D37)^4 + G7/(1+D37)^5)+$C$8*B40/(1+D37)^5+$C$16)/$C$17 -> 456.14378 | E40: =((C7/(1+E37)^1 + D7/(1+E37)^2 + E7/(1+E37)^3 + F7/(1+E37)^4 + G7/(1+E37)^5)+$C$8*B40/(1+E37)^5+$C$16)/$C$17 -> 441.1657 | F40: =((C7/(1+F37)^1 + D7/(1+F37)^2 + E7/(1+F37)^3 + F7/(1+F37)^4 + G7/(1+F37)^5)+$C$8*B40/(1+F37)^5+$C$16)/$C$17 -> 428.57247 | G40: =((C7/(1+G37)^1 + D7/(1+G37)^2 + E7/(1+G37)^3 + F7/(1+G37)^4 + G7/(1+G37)^5)+$C$8*B40/(1+G37)^5+$C$16)/$C$17 -> 411.37018
B41: 21 | C41: =((C7/(1+C37)^1 + D7/(1+C37)^2 + E7/(1+C37)^3 + F7/(1+C37)^4 + G7/(1+C37)^5)+$C$8*B41/(1+C37)^5+$C$16)/$C$17 -> 543.52604 | D41: =((C7/(1+D37)^1 + D7/(1+D37)^2 + E7/(1+D37)^3 + F7/(1+D37)^4 + G7/(1+D37)^5)+$C$8*B41/(1+D37)^5+$C$16)/$C$17 -> 520.86764 | E41: =((C7/(1+E37)^1 + D7/(1+E37)^2 + E7/(1+E37)^3 + F7/(1+E37)^4 + G7/(1+E37)^5)+$C$8*B41/(1+E37)^5+$C$16)/$C$17 -> 503.59665 | F41: =((C7/(1+F37)^1 + D7/(1+F37)^2 + E7/(1+F37)^3 + F7/(1+F37)^4 + G7/(1+F37)^5)+$C$8*B41/(1+F37)^5+$C$16)/$C$17 -> 489.07668 | G41: =((C7/(1+G37)^1 + D7/(1+G37)^2 + E7/(1+G37)^3 + F7/(1+G37)^4 + G7/(1+G37)^5)+$C$8*B41/(1+G37)^5+$C$16)/$C$17 -> 469.24418
B42: 24 | C42: =((C7/(1+C37)^1 + D7/(1+C37)^2 + E7/(1+C37)^3 + F7/(1+C37)^4 + G7/(1+C37)^5)+$C$8*B42/(1+C37)^5+$C$16)/$C$17 -> 611.2598 | D42: =((C7/(1+D37)^1 + D7/(1+D37)^2 + E7/(1+D37)^3 + F7/(1+D37)^4 + G7/(1+D37)^5)+$C$8*B42/(1+D37)^5+$C$16)/$C$17 -> 585.59149 | E42: =((C7/(1+E37)^1 + D7/(1+E37)^2 + E7/(1+E37)^3 + F7/(1+E37)^4 + G7/(1+E37)^5)+$C$8*B42/(1+E37)^5+$C$16)/$C$17 -> 566.0276 | F42: =((C7/(1+F37)^1 + D7/(1+F37)^2 + E7/(1+F37)^3 + F7/(1+F37)^4 + G7/(1+F37)^5)+$C$8*B42/(1+F37)^5+$C$16)/$C$17 -> 549.5809 | G42: =((C7/(1+G37)^1 + D7/(1+G37)^2 + E7/(1+G37)^3 + F7/(1+G37)^4 + G7/(1+G37)^5)+$C$8*B42/(1+G37)^5+$C$16)/$C$17 -> 527.11819
B44: Base case (WACC 11.3%, 18x) highlighted in green
B47: TABLE 3: Upside/(Downside) vs $995 — Gordon Growth
B48: Current price: | C48: 995
B49: g \ WACC | C49: 0.095 | D49: 0.105 | E49: 0.113 | F49: 0.12 | G49: 0.13
B50: 0.015 | C50: =IFERROR(C24/$C$48-1,"-") -> -0.7497857 | D50: =IFERROR(D24/$C$48-1,"-") -> -0.77856441 | E50: =IFERROR(E24/$C$48-1,"-") -> -0.79729229 | F50: =IFERROR(F24/$C$48-1,"-") -> -0.81129463 | G50: =IFERROR(G24/$C$48-1,"-") -> -0.82827881
B51: 0.02 | C51: =IFERROR(C25/$C$48-1,"-") -> -0.73680567 | D51: =IFERROR(D25/$C$48-1,"-") -> -0.76874754 | E51: =IFERROR(E25/$C$48-1,"-") -> -0.78928669 | F51: =IFERROR(F25/$C$48-1,"-") -> -0.80451787 | G51: =IFERROR(G25/$C$48-1,"-") -> -0.82285032
B52: 0.025 | C52: =IFERROR(C26/$C$48-1,"-") -> -0.72197134 | D52: =IFERROR(D26/$C$48-1,"-") -> -0.75770356 | E52: =IFERROR(E26/$C$48-1,"-") -> -0.78037136 | F52: =IFERROR(F26/$C$48-1,"-") -> -0.79702776 | G52: =IFERROR(G26/$C$48-1,"-") -> -0.81690482
B53: 0.03 | C53: =IFERROR(C27/$C$48-1,"-") -> -0.70485481 | D53: =IFERROR(D27/$C$48-1,"-") -> -0.74518704 | E53: =IFERROR(E27/$C$48-1,"-") -> -0.77038189 | F53: =IFERROR(F27/$C$48-1,"-") -> -0.78870542 | G53: =IFERROR(G27/$C$48-1,"-") -> -0.81036478
...

Sheet Scenarios
B2: SCENARIO ANALYSIS
B3: Toggle scenario by changing cell C5. Model pulls the matching column (Bear/Base/Bull) from the table below.
B5: ACTIVE SCENARIO: | C5: Base | D5: ← Type "Bear", "Base", or "Bull"
B6: Column index: | C6: =MATCH(C5,{"Bear","Base","Bull"},0) -> 2
B8: LIVE OUTPUT (reflects active scenario from DCF tab)
B10: WACC | C10: =Assumptions!C56 -> 0.113035 | D10: Terminal g | E10: =Assumptions!C58 -> 0.025 | F10: IMPLIED PRICE | G10: UPSIDE vs $995
B11: 2030E Revenue | C11: =Revenue!J28 -> 62744.823 | D11: 2030E EBITDA | E11: ='P&L'!J21 -> 9241.1891 | F11: =DCF!C48 -> 218.44096 | G11: =DCF!C51 -> -0.78046135
B13: To compare scenarios: toggle C5 above. To view all three simultaneously: see summary table at bottom.
B16: SCENARIO ASSUMPTION TABLES
B18: Assumption | C18: Bear | D18: Base | E18: Bull | F18: Active | G18: Note
B19: REVENUE GROWTH (by sub-segment, by year)
B20: Gas Power growth 2026E | C20: 0.12 | D20: 0.15 | E20: 0.17 | F20: =INDEX(C20:E20,$C$6) -> 0.15
B21: Gas Power growth 2027E | C21: 0.09 | D21: 0.13 | E21: 0.15 | F21: =INDEX(C21:E21,$C$6) -> 0.13
B22: Gas Power growth 2028E | C22: 0.06 | D22: 0.11 | E22: 0.13 | F22: =INDEX(C22:E22,$C$6) -> 0.11
B23: Gas Power growth 2029E | C23: 0.04 | D23: 0.09 | E23: 0.11 | F23: =INDEX(C23:E23,$C$6) -> 0.09
B24: Gas Power growth 2030E | C24: 0.03 | D24: 0.07 | E24: 0.1 | F24: =INDEX(C24:E24,$C$6) -> 0.07
B25: Nuclear Power growth 2026E | C25: 0.12 | D25: 0.15 | E25: 0.18 | F25: =INDEX(C25:E25,$C$6) -> 0.15
B26: Nuclear Power growth 2027E | C26: 0.1 | D26: 0.15 | E26: 0.18 | F26: =INDEX(C26:E26,$C$6) -> 0.15
B27: Nuclear Power growth 2028E | C27: 0.08 | D27: 0.14 | E27: 0.16 | F27: =INDEX(C27:E27,$C$6) -> 0.14
B28: Nuclear Power growth 2029E | C28: 0.06 | D28: 0.12 | E28: 0.14 | F28: =INDEX(C28:E28,$C$6) -> 0.12
B29: Nuclear Power growth 2030E | C29: 0.05 | D29: 0.1 | E29: 0.12 | F29: =INDEX(C29:E29,$C$6) -> 0.1
B30: Hydro Power growth 2026E | C30: 0.03 | D30: 0.03 | E30: 0.03 | F30: =INDEX(C30:E30,$C$6) -> 0.03
B31: Hydro Power growth 2027E | C31: 0.03 | D31: 0.03 | E31: 0.03 | F31: =INDEX(C31:E31,$C$6) -> 0.03
... B69: Electrification Software growth 2030E | C69: 0.06 | D69: 0.06 | E69: 0.06 | F69: =INDEX(C69:E69,$C$6) -> 0.06
B71: SEGMENT EBITDA MARGINS
B72: Power EBITDA margin 2026E | C72: 0.15 | D72: 0.16 | E72: 0.17 | F72: =INDEX(C72:E72,$C$6) -> 0.16
B73: Power EBITDA margin 2027E | C73: 0.155 | D73: 0.17 | E73: 0.18 | F73: =INDEX(C73:E73,$C$6) -> 0.17
B74: Power EBITDA margin 2028E | C74: 0.16 | D74: 0.175 | E74: 0.19 | F74: =INDEX(C74:E74,$C$6) -> 0.175
B75: Power EBITDA margin 2029E | C75: 0.16 | D75: 0.18 | E75: 0.195 | F75: =INDEX(C75:E75,$C$6) -> 0.18
B76: Power EBITDA margin 2030E | C76: 0.16 | D76: 0.18 | E76: 0.2 | F76: =INDEX(C76:E76,$C$6) -> 0.18
B77: Wind EBITDA margin 2026E | C77: -0.06 | D77: -0.045 | E77: -0.03 | F77: =INDEX(C77:E77,$C$6) -> -0.045
B78: Wind EBITDA margin 2027E | C78: -0.05 | D78: -0.025 | E78: -0.01 | F78: =INDEX(C78:E78,$C$6) -> -0.025
B79: Wind EBITDA margin 2028E | C79: -0.04 | D79: -0.01 | E79: 0.01 | F79: =INDEX(C79:E79,$C$6) -> -0.01
B80: Wind EBITDA margin 2029E | C80: -0.03 | D80: 0.005 | E80: 0.03 | F80: =INDEX(C80:E80,$C$6) -> 0.005
B81: Wind EBITDA margin 2030E | C81: -0.02 | D81: 0.015 | E81: 0.05 | F81: =INDEX(C81:E81,$C$6) -> 0.015
B82: Electrification EBITDA margin 2026E | C82: 0.155 | D82: 0.17 | E82: 0.175 | F82: =INDEX(C82:E82,$C$6) -> 0.17
B83: Electrification EBITDA margin 2027E | C83: 0.16 | D83: 0.18 | E83: 0.19 | F83: =INDEX(C83:E83,$C$6) -> 0.18
... B86: Electrification EBITDA margin 2030E | C86: 0.16 | D86: 0.19 | E86: 0.21 | F86: =INDEX(C86:E86,$C$6) -> 0.19
B88: WACC & TERMINAL
B89: Beta | C89: 1.45 | D89: 1.3 | E89: 1.15 | F89: =INDEX(C89:E89,$C$6) -> 1.3 | G89: Higher in Bear (more risk), lower in Bull (AI premium accepted)
...

Sheet Comps
B2: COMPARABLE COMPANIES ANALYSIS
B3: Trading multiples as of April 10-14, 2026. Applied to GEV forecasts to derive implied valuation.
B5: PEER GROUP TRADING MULTIPLES
B7: Company | C7: Ticker | D7: Market Cap ($B) | E7: EV ($B) | F7: Rev TTM ($B) | G7: EBITDA TTM ($B) | H7: EBITDA margin | I7: Rev growth (LTM) | J7: EV/Rev | K7: EV/EBITDA (TTM) | L7: EV/EBITDA (FWD) | M7: P/E (TTM) | N7: P/E (FWD)
B8: Eaton | C8: ETN | D8: 151.2 | E8: 155 | F8: 26.1 | G8: 6.18 | H8: 0.237 | I8: 0.091 | J8: 5.94 | K8: 24 | L8: 20.5 | M8: 34.2 | N8: 27.1
B9: Emerson Electric | C9: EMR | D9: 68.7 | E9: 73.5 | F9: 17.55 | G9: 4.77 | H9: 0.272 | I9: 0.105 | J9: 4.19 | K9: 15.4 | L9: 14.3 | M9: 28.9 | N9: 22.3
B10: Siemens Energy | C10: ENR.DE | D10: 85 | E10: 78 | F10: 45 | G10: 3.2 | H10: 0.071 | I10: 0.17 | J10: 1.73 | K10: 28.9 | L10: 14 | M10: 71.5 | N10: 34.3
B11: ABB | C11: ABBNY | D11: 164.8 | E11: 167.3 | F11: 33.2 | G11: 7.1 | H11: 0.214 | I11: 0.066 | J11: 5.04 | K11: 23.5 | L11: 19 | M11: 36.4 | N11: 29.3
B12: Hubbell | C12: HUBB | D12: 28.5 | E12: 30.1 | F12: 5.91 | G12: 1.41 | H12: 0.239 | I12: 0.059 | J12: 5.09 | K12: 21.3 | L12: 18.5 | M12: 31.9 | N12: 26.7
B13: Schneider Electric | C13: SBGSY | D13: 215 | E13: 225 | F13: 43 | G13: 8.5 | H13: 0.198 | I13: 0.084 | J13: 5.23 | K13: 26.5 | L13: 22 | M13: 33.5 | N13: 27
B14: Rockwell Automation | C14: ROK | D14: 40.5 | E14: 44 | F14: 8.5 | G14: 1.7 | H14: 0.2 | I14: 0.035 | J14: 5.18 | K14: 25.9 | L14: 21 | M14: 40.2 | N14: 30
B15: Vertiv | C15: VRT | D15: 70 | E15: 72 | F15: 10.5 | G15: 2.1 | H15: 0.2 | I15: 0.175 | J15: 6.86 | K15: 46 | L15: 28.5 | M15: 76.7 | N15: 42.5
B16: Quanta Services | C16: PWR | D16: 60 | E16: 64 | F16: 26.5 | G16: 2.4 | H16: 0.091 | I16: 0.135 | J16: 2.42 | K16: 36 | L16: 25 | M16: 82.5 | N16: 42.8
B18: GE Vernova (Subject) | C18: GEV | D18: 268.7 | E18: 262.6 | F18: 38.1 | G18: 3.2 | H18: 0.084 | I18: 0.09 | J18: =E18/F18 -> 6.8923885 | K18: =E18/G18 -> 82.0625 | L18: =E18/'P&L'!F21 -> 0.05254907 | M18: 165.00829 | N18: =995/'P&L'!F43 -> 95.023449
B20: PEER STATISTICS
B21: Max | H21: =MAX(H8:H16) -> 0.272 | I21: =MAX(I8:I16) -> 0.175 | J21: =MAX(J8:J16) -> 6.86 | K21: =MAX(K8:K16) -> 46 | L21: =MAX(L8:L16) -> 28.5 | M21: =MAX(M8:M16) -> 82.5 | N21: =MAX(N8:N16) -> 42.8
B22: Min | H22: =MIN(H8:H16) -> 0.071 | I22: =MIN(I8:I16) -> 0.035 | J22: =MIN(J8:J16) -> 1.73 | K22: =MIN(K8:K16) -> 15.4 | L22: =MIN(L8:L16) -> 14 | M22: =MIN(M8:M16) -> 28.9 | N22: =MIN(N8:N16) -> 22.3
B23: Mean | H23: =AVERAGE(H8:H16) -> 0.19133333 | I23: =AVERAGE(I8:I16) -> 0.10222222 | J23: =AVERAGE(J8:J16) -> 4.6311111 | K23: =AVERAGE(K8:K16) -> 27.5 | L23: =AVERAGE(L8:L16) -> 20.311111 | M23: =AVERAGE(M8:M16) -> 48.422222 | N23: =AVERAGE(N8:N16) -> 31.333333
B24: Median | H24: =MEDIAN(H8:H16) -> 0.2 | I24: =MEDIAN(I8:I16) -> 0.091 | J24: =MEDIAN(J8:J16) -> 5.09 | K24: =MEDIAN(K8:K16) -> 25.9 | L24: =MEDIAN(L8:L16) -> 20.5 | M24: =MEDIAN(M8:M16) -> 36.4 | N24: =MEDIAN(N8:N16) -> 29.3
B25: Tier 1 median (direct peers) | H25: =MEDIAN(H8:H12) -> 0.237 | I25: =MEDIAN(I8:I12) -> 0.091 | J25: =MEDIAN(J8:J12) -> 5.04 | K25: =MEDIAN(K8:K12) -> 23.5 | L25: =MEDIAN(L8:L12) -> 18.5 | M25: =MEDIAN(M8:M12) -> 34.2 | N25: =MEDIAN(N8:N12) -> 27.1
B28: IMPLIED GEV VALUATION FROM PEER MULTIPLES
B29: Applying peer median and Tier 1 median multiples to GEV 2026E and 2027E estimates.
B31: Method | C31: GEV Metric | D31: Multiple (Peer Median) | E31: Multiple (Tier 1 Median) | F31: Implied Value (Peer Med) | G31: Implied Value (Tier 1) | H31: Implied Price/Share
B32: Net bridge ($M, EV→Equity adjustment) | C32: 5314
B33: Diluted shares (M) | C33: 270
B35: EV/Rev × 2026E Revenue | C35: =Revenue!F28/1000 -> 44.98983 | D35: =J24 -> 5.09 | E35: =J25 -> 5.04 | F35: =C35*D35*1000 -> 228998.23 | G35: =C35*E35*1000 -> 226748.74 | H35: =(G35+$C$32)/$C$33 -> 859.49164
B36: EV/EBITDA × 2026E EBITDA | C36: ='P&L'!F21/1000 -> 4.9972341 | D36: =L24 -> 20.5 | E36: =L25 -> 18.5 | F36: =C36*D36*1000 -> 102443.3 | G36: =C36*E36*1000 -> 92448.83 | H36: =(G36+$C$32)/$C$33 -> 362.08456
B37: EV/EBITDA × 2027E EBITDA | C37: ='P&L'!G21/1000 -> 6.3141659 | D37: =L24 -> 20.5 | E37: =L25 -> 18.5 | F37: =C37*D37*1000 -> 129440.4 | G37: =C37*E37*1000 -> 116812.07 | H37: =(G37+$C$32)/$C$33 -> 452.31878
B38: P/E × 2026E EPS (forward) | C38: ='P&L'!F43 -> 10.4711 | D38: =N24 -> 29.3 | E38: =N25 -> 27.1 | F38: =C38*D38*$C$33 -> 82836.869 | G38: =C38*E38*$C$33 -> 76617.036 | H38: =C38*E38 -> 283.7668
B39: P/E × 2027E EPS | C39: ='P&L'!G43 -> 14.192596 | D39: =N24 -> 29.3 | E39: =N25 -> 27.1 | F39: =C39*D39*$C$33 -> 112277.63 | G39: =C39*E39*$C$33 -> 103847.23 | H39: =C39*E39 -> 384.61936
B41: RANGE OF IMPLIED PRICES (Tier 1 median multiples)
B42: Minimum | H42: =MIN(H35:H39) -> 283.7668
B43: Maximum | H43: =MAX(H35:H39) -> 859.49164
B44: Mean | H44: =AVERAGE(H35:H39) -> 468.45623
B45: Median | H45: =MEDIAN(H35:H39) -> 384.61936
B47: Current market price | H47: 995
B48: Upside/(Downside) vs mean | H48: =H43/H47-1 -> -0.13618931
B51: KEY OBSERVATIONS
B52: 1. GEV trades at a MASSIVE premium to direct peers (Eaton, Emerson, ABB, Hubbell) on every multiple.
B53: 2. Vertiv and Quanta Services trade at elevated multiples due to AI data-center narrative — GEV trades even higher.
...
